{
 "cells": [
  {
   "cell_type": "code",
   "execution_count": 1,
   "metadata": {},
   "outputs": [],
   "source": [
    "#Building the framework for the app\n",
    "from flask import Flask, render_template, redirect, url_for\n",
    "from pymongo import MongoClient\n",
    "from flask_pymongo import PyMongo\n",
    "import pymongo\n",
    "#import requests\n",
    "import scraping"
   ]
  },
  {
   "cell_type": "code",
   "execution_count": 2,
   "metadata": {},
   "outputs": [],
   "source": [
    "#helpful link https://stackoverflow.com/questions/23327293/flask-raises-templatenotfound-error-even-though-template-file-exists\n",
    "app = Flask(__name__, template_folder='template/')"
   ]
  },
  {
   "cell_type": "code",
   "execution_count": 3,
   "metadata": {},
   "outputs": [],
   "source": [
    "\n",
    "#client = pymongo.MongoClient(\"mongodb://star01:EiTtZkI2Ya2vcYtO@cluster0-shard-00-00.jo5zk.mongodb.net:27017,cluster0-shard-00-01.jo5zk.mongodb.net:27017,cluster0-shard-00-02.jo5zk.mongodb.net:27017/mars_app?ssl=true&replicaSet=atlas-yfm4hf-shard-0&authSource=admin&retryWrites=true&w=majority\")\n",
    "#mydb = client.mars_app\n",
    "#mycol = mydb.mars_app"
   ]
  },
  {
   "cell_type": "code",
   "execution_count": 4,
   "metadata": {},
   "outputs": [],
   "source": [
    "#app.config['MONGO_HOST'] = 'localhost'\n",
    "#app.config['MONGO_PORT'] = '27017'\n",
    "#app.config['MONGO_DBNAME'] = 'mars_app'\n",
    "#app.config['MONGO_USERNAME'] = 'star01'\n",
    "#app.config['MONGO_PASSWORD'] = 'EiTtZkI2Ya2vcYtO'\n",
    "#app.config['MONGO_AUTH_SOURCE'] = 'admin'  # root user is typically defined in admin db"
   ]
  },
  {
   "cell_type": "code",
   "execution_count": 5,
   "metadata": {},
   "outputs": [],
   "source": [
    "\n",
    "app.config['MONGO_URI'] =  \"mongodb+srv://star01:EiTtZkI2Ya2vcYtO@cluster0.jo5zk.mongodb.net/mars_app?retryWrites=true&w=majority\""
   ]
  },
  {
   "cell_type": "code",
   "execution_count": 6,
   "metadata": {},
   "outputs": [],
   "source": [
    "mongo = PyMongo(app)"
   ]
  },
  {
   "cell_type": "code",
   "execution_count": 7,
   "metadata": {},
   "outputs": [],
   "source": [
    "# Use flask_pymongo to set up mongo connection\n",
    "#app.config[\"MONGO_URI\"] = app.config[\"MONGO_URI\"] = \"mongodb://star01:EiTtZkI2Ya2vcYtO@localhost:27017/mars_app?authSource=admin\"\n",
    "#mongo = PyMongo(app)"
   ]
  },
  {
   "cell_type": "code",
   "execution_count": 8,
   "metadata": {},
   "outputs": [],
   "source": [
    "#define the route of the HTML page\n",
    "@app.route(\"/\")\n",
    "def index():\n",
    "    mars = mongo.db.mars.find_one()\n",
    "    return render_template(\"index.html\", mars=mars)"
   ]
  },
  {
   "cell_type": "code",
   "execution_count": 9,
   "metadata": {},
   "outputs": [],
   "source": [
    "@app.route(\"/scrape\")\n",
    "def scrape():\n",
    "    mars = mongo.db.mars\n",
    "    mars_data = scraping.scrape_all()\n",
    "    mars.update_one({}, {\"$set\":mars_data}, upsert=True)\n",
    "    return redirect('/', code=302)"
   ]
  },
  {
   "cell_type": "code",
   "execution_count": null,
   "metadata": {},
   "outputs": [
    {
     "name": "stdout",
     "output_type": "stream",
     "text": [
      " * Serving Flask app \"__main__\" (lazy loading)\n",
      " * Environment: production\n",
      "   WARNING: This is a development server. Do not use it in a production deployment.\n",
      "   Use a production WSGI server instead.\n",
      " * Debug mode: off\n"
     ]
    },
    {
     "name": "stderr",
     "output_type": "stream",
     "text": [
      " * Running on http://127.0.0.1:5000/ (Press CTRL+C to quit)\n",
      "127.0.0.1 - - [26/Jan/2022 05:45:21] \"\u001b[37mGET / HTTP/1.1\u001b[0m\" 200 -\n",
      "127.0.0.1 - - [26/Jan/2022 05:46:44] \"\u001b[37mGET / HTTP/1.1\u001b[0m\" 200 -\n",
      "\n",
      "\n",
      "====== WebDriver manager ======\n",
      "Current google-chrome version is 97.0.4692\n",
      "Get LATEST chromedriver version for 97.0.4692 google-chrome\n",
      "Driver [C:\\Users\\bdaob\\.wdm\\drivers\\chromedriver\\win32\\97.0.4692.71\\chromedriver.exe] found in cache\n",
      "[2022-01-26 05:46:53,828] ERROR in app: Exception on /scrape [GET]\n",
      "Traceback (most recent call last):\n",
      "  File \"C:\\Users\\bdaob\\anaconda3\\envs\\PythonData\\lib\\site-packages\\flask\\app.py\", line 2447, in wsgi_app\n",
      "    response = self.full_dispatch_request()\n",
      "  File \"C:\\Users\\bdaob\\anaconda3\\envs\\PythonData\\lib\\site-packages\\flask\\app.py\", line 1952, in full_dispatch_request\n",
      "    rv = self.handle_user_exception(e)\n",
      "  File \"C:\\Users\\bdaob\\anaconda3\\envs\\PythonData\\lib\\site-packages\\flask\\app.py\", line 1821, in handle_user_exception\n",
      "    reraise(exc_type, exc_value, tb)\n",
      "  File \"C:\\Users\\bdaob\\anaconda3\\envs\\PythonData\\lib\\site-packages\\flask\\_compat.py\", line 39, in reraise\n",
      "    raise value\n",
      "  File \"C:\\Users\\bdaob\\anaconda3\\envs\\PythonData\\lib\\site-packages\\flask\\app.py\", line 1950, in full_dispatch_request\n",
      "    rv = self.dispatch_request()\n",
      "  File \"C:\\Users\\bdaob\\anaconda3\\envs\\PythonData\\lib\\site-packages\\flask\\app.py\", line 1936, in dispatch_request\n",
      "    return self.view_functions[rule.endpoint](**req.view_args)\n",
      "  File \"<ipython-input-9-00786c70c104>\", line 5, in scrape\n",
      "    mars.update_one({}, {\"$set\":mars_data}, upsert=True)\n",
      "  File \"C:\\Users\\bdaob\\anaconda3\\envs\\PythonData\\lib\\site-packages\\pymongo\\collection.py\", line 833, in update_one\n",
      "    hint=hint, session=session),\n",
      "  File \"C:\\Users\\bdaob\\anaconda3\\envs\\PythonData\\lib\\site-packages\\pymongo\\collection.py\", line 679, in _update_retryable\n",
      "    _update, session)\n",
      "  File \"C:\\Users\\bdaob\\anaconda3\\envs\\PythonData\\lib\\site-packages\\pymongo\\mongo_client.py\", line 1340, in _retryable_write\n",
      "    return self._retry_with_session(retryable, func, s, None)\n",
      "  File \"C:\\Users\\bdaob\\anaconda3\\envs\\PythonData\\lib\\site-packages\\pymongo\\mongo_client.py\", line 1229, in _retry_with_session\n",
      "    return self._retry_internal(retryable, func, session, bulk)\n",
      "  File \"C:\\Users\\bdaob\\anaconda3\\envs\\PythonData\\lib\\site-packages\\pymongo\\mongo_client.py\", line 1261, in _retry_internal\n",
      "    return func(session, sock_info, retryable)\n",
      "  File \"C:\\Users\\bdaob\\anaconda3\\envs\\PythonData\\lib\\site-packages\\pymongo\\collection.py\", line 675, in _update\n",
      "    retryable_write=retryable_write)\n",
      "  File \"C:\\Users\\bdaob\\anaconda3\\envs\\PythonData\\lib\\site-packages\\pymongo\\collection.py\", line 645, in _update\n",
      "    retryable_write=retryable_write).copy()\n",
      "  File \"C:\\Users\\bdaob\\anaconda3\\envs\\PythonData\\lib\\site-packages\\pymongo\\pool.py\", line 735, in command\n",
      "    self._raise_connection_failure(error)\n",
      "  File \"C:\\Users\\bdaob\\anaconda3\\envs\\PythonData\\lib\\site-packages\\pymongo\\pool.py\", line 730, in command\n",
      "    exhaust_allowed=exhaust_allowed)\n",
      "  File \"C:\\Users\\bdaob\\anaconda3\\envs\\PythonData\\lib\\site-packages\\pymongo\\network.py\", line 120, in command\n",
      "    codec_options, ctx=compression_ctx)\n",
      "  File \"C:\\Users\\bdaob\\anaconda3\\envs\\PythonData\\lib\\site-packages\\pymongo\\message.py\", line 598, in _op_msg\n",
      "    flags, command, identifier, docs, check_keys, opts)\n",
      "bson.errors.InvalidDocument: cannot encode object: <built-in method now of type object at 0x00000000688F2280>, of type: <class 'builtin_function_or_method'>\n",
      "127.0.0.1 - - [26/Jan/2022 05:46:53] \"\u001b[35m\u001b[1mGET /scrape HTTP/1.1\u001b[0m\" 500 -\n",
      "127.0.0.1 - - [26/Jan/2022 05:51:34] \"\u001b[37mGET / HTTP/1.1\u001b[0m\" 200 -\n",
      "\n",
      "\n",
      "====== WebDriver manager ======\n",
      "Current google-chrome version is 97.0.4692\n",
      "Get LATEST chromedriver version for 97.0.4692 google-chrome\n",
      "Driver [C:\\Users\\bdaob\\.wdm\\drivers\\chromedriver\\win32\\97.0.4692.71\\chromedriver.exe] found in cache\n",
      "[2022-01-26 05:51:40,597] ERROR in app: Exception on /scrape [GET]\n",
      "Traceback (most recent call last):\n",
      "  File \"C:\\Users\\bdaob\\anaconda3\\envs\\PythonData\\lib\\site-packages\\flask\\app.py\", line 2447, in wsgi_app\n",
      "    response = self.full_dispatch_request()\n",
      "  File \"C:\\Users\\bdaob\\anaconda3\\envs\\PythonData\\lib\\site-packages\\flask\\app.py\", line 1952, in full_dispatch_request\n",
      "    rv = self.handle_user_exception(e)\n",
      "  File \"C:\\Users\\bdaob\\anaconda3\\envs\\PythonData\\lib\\site-packages\\flask\\app.py\", line 1821, in handle_user_exception\n",
      "    reraise(exc_type, exc_value, tb)\n",
      "  File \"C:\\Users\\bdaob\\anaconda3\\envs\\PythonData\\lib\\site-packages\\flask\\_compat.py\", line 39, in reraise\n",
      "    raise value\n",
      "  File \"C:\\Users\\bdaob\\anaconda3\\envs\\PythonData\\lib\\site-packages\\flask\\app.py\", line 1950, in full_dispatch_request\n",
      "    rv = self.dispatch_request()\n",
      "  File \"C:\\Users\\bdaob\\anaconda3\\envs\\PythonData\\lib\\site-packages\\flask\\app.py\", line 1936, in dispatch_request\n",
      "    return self.view_functions[rule.endpoint](**req.view_args)\n",
      "  File \"<ipython-input-9-00786c70c104>\", line 5, in scrape\n",
      "    mars.update_one({}, {\"$set\":mars_data}, upsert=True)\n",
      "  File \"C:\\Users\\bdaob\\anaconda3\\envs\\PythonData\\lib\\site-packages\\pymongo\\collection.py\", line 833, in update_one\n",
      "    hint=hint, session=session),\n",
      "  File \"C:\\Users\\bdaob\\anaconda3\\envs\\PythonData\\lib\\site-packages\\pymongo\\collection.py\", line 679, in _update_retryable\n",
      "    _update, session)\n",
      "  File \"C:\\Users\\bdaob\\anaconda3\\envs\\PythonData\\lib\\site-packages\\pymongo\\mongo_client.py\", line 1340, in _retryable_write\n",
      "    return self._retry_with_session(retryable, func, s, None)\n",
      "  File \"C:\\Users\\bdaob\\anaconda3\\envs\\PythonData\\lib\\site-packages\\pymongo\\mongo_client.py\", line 1229, in _retry_with_session\n",
      "    return self._retry_internal(retryable, func, session, bulk)\n",
      "  File \"C:\\Users\\bdaob\\anaconda3\\envs\\PythonData\\lib\\site-packages\\pymongo\\mongo_client.py\", line 1261, in _retry_internal\n",
      "    return func(session, sock_info, retryable)\n",
      "  File \"C:\\Users\\bdaob\\anaconda3\\envs\\PythonData\\lib\\site-packages\\pymongo\\collection.py\", line 675, in _update\n",
      "    retryable_write=retryable_write)\n",
      "  File \"C:\\Users\\bdaob\\anaconda3\\envs\\PythonData\\lib\\site-packages\\pymongo\\collection.py\", line 645, in _update\n",
      "    retryable_write=retryable_write).copy()\n",
      "  File \"C:\\Users\\bdaob\\anaconda3\\envs\\PythonData\\lib\\site-packages\\pymongo\\pool.py\", line 735, in command\n",
      "    self._raise_connection_failure(error)\n",
      "  File \"C:\\Users\\bdaob\\anaconda3\\envs\\PythonData\\lib\\site-packages\\pymongo\\pool.py\", line 730, in command\n",
      "    exhaust_allowed=exhaust_allowed)\n",
      "  File \"C:\\Users\\bdaob\\anaconda3\\envs\\PythonData\\lib\\site-packages\\pymongo\\network.py\", line 120, in command\n",
      "    codec_options, ctx=compression_ctx)\n",
      "  File \"C:\\Users\\bdaob\\anaconda3\\envs\\PythonData\\lib\\site-packages\\pymongo\\message.py\", line 598, in _op_msg\n",
      "    flags, command, identifier, docs, check_keys, opts)\n",
      "bson.errors.InvalidDocument: cannot encode object: <built-in method now of type object at 0x00000000688F2280>, of type: <class 'builtin_function_or_method'>\n",
      "127.0.0.1 - - [26/Jan/2022 05:51:40] \"\u001b[35m\u001b[1mGET /scrape HTTP/1.1\u001b[0m\" 500 -\n",
      "127.0.0.1 - - [26/Jan/2022 05:53:25] \"\u001b[37mGET / HTTP/1.1\u001b[0m\" 200 -\n",
      "\n",
      "\n",
      "====== WebDriver manager ======\n",
      "Current google-chrome version is 97.0.4692\n",
      "Get LATEST chromedriver version for 97.0.4692 google-chrome\n",
      "Driver [C:\\Users\\bdaob\\.wdm\\drivers\\chromedriver\\win32\\97.0.4692.71\\chromedriver.exe] found in cache\n",
      "[2022-01-26 05:53:33,054] ERROR in app: Exception on /scrape [GET]\n",
      "Traceback (most recent call last):\n",
      "  File \"C:\\Users\\bdaob\\anaconda3\\envs\\PythonData\\lib\\site-packages\\flask\\app.py\", line 2447, in wsgi_app\n",
      "    response = self.full_dispatch_request()\n",
      "  File \"C:\\Users\\bdaob\\anaconda3\\envs\\PythonData\\lib\\site-packages\\flask\\app.py\", line 1952, in full_dispatch_request\n",
      "    rv = self.handle_user_exception(e)\n",
      "  File \"C:\\Users\\bdaob\\anaconda3\\envs\\PythonData\\lib\\site-packages\\flask\\app.py\", line 1821, in handle_user_exception\n",
      "    reraise(exc_type, exc_value, tb)\n",
      "  File \"C:\\Users\\bdaob\\anaconda3\\envs\\PythonData\\lib\\site-packages\\flask\\_compat.py\", line 39, in reraise\n",
      "    raise value\n",
      "  File \"C:\\Users\\bdaob\\anaconda3\\envs\\PythonData\\lib\\site-packages\\flask\\app.py\", line 1950, in full_dispatch_request\n",
      "    rv = self.dispatch_request()\n",
      "  File \"C:\\Users\\bdaob\\anaconda3\\envs\\PythonData\\lib\\site-packages\\flask\\app.py\", line 1936, in dispatch_request\n",
      "    return self.view_functions[rule.endpoint](**req.view_args)\n",
      "  File \"<ipython-input-9-00786c70c104>\", line 5, in scrape\n",
      "    mars.update_one({}, {\"$set\":mars_data}, upsert=True)\n",
      "  File \"C:\\Users\\bdaob\\anaconda3\\envs\\PythonData\\lib\\site-packages\\pymongo\\collection.py\", line 833, in update_one\n",
      "    hint=hint, session=session),\n",
      "  File \"C:\\Users\\bdaob\\anaconda3\\envs\\PythonData\\lib\\site-packages\\pymongo\\collection.py\", line 679, in _update_retryable\n",
      "    _update, session)\n",
      "  File \"C:\\Users\\bdaob\\anaconda3\\envs\\PythonData\\lib\\site-packages\\pymongo\\mongo_client.py\", line 1340, in _retryable_write\n",
      "    return self._retry_with_session(retryable, func, s, None)\n",
      "  File \"C:\\Users\\bdaob\\anaconda3\\envs\\PythonData\\lib\\site-packages\\pymongo\\mongo_client.py\", line 1229, in _retry_with_session\n",
      "    return self._retry_internal(retryable, func, session, bulk)\n",
      "  File \"C:\\Users\\bdaob\\anaconda3\\envs\\PythonData\\lib\\site-packages\\pymongo\\mongo_client.py\", line 1261, in _retry_internal\n",
      "    return func(session, sock_info, retryable)\n",
      "  File \"C:\\Users\\bdaob\\anaconda3\\envs\\PythonData\\lib\\site-packages\\pymongo\\collection.py\", line 675, in _update\n",
      "    retryable_write=retryable_write)\n",
      "  File \"C:\\Users\\bdaob\\anaconda3\\envs\\PythonData\\lib\\site-packages\\pymongo\\collection.py\", line 645, in _update\n",
      "    retryable_write=retryable_write).copy()\n",
      "  File \"C:\\Users\\bdaob\\anaconda3\\envs\\PythonData\\lib\\site-packages\\pymongo\\pool.py\", line 735, in command\n",
      "    self._raise_connection_failure(error)\n",
      "  File \"C:\\Users\\bdaob\\anaconda3\\envs\\PythonData\\lib\\site-packages\\pymongo\\pool.py\", line 730, in command\n",
      "    exhaust_allowed=exhaust_allowed)\n",
      "  File \"C:\\Users\\bdaob\\anaconda3\\envs\\PythonData\\lib\\site-packages\\pymongo\\network.py\", line 120, in command\n",
      "    codec_options, ctx=compression_ctx)\n",
      "  File \"C:\\Users\\bdaob\\anaconda3\\envs\\PythonData\\lib\\site-packages\\pymongo\\message.py\", line 598, in _op_msg\n",
      "    flags, command, identifier, docs, check_keys, opts)\n",
      "bson.errors.InvalidDocument: cannot encode object: <built-in method now of type object at 0x00000000688F2280>, of type: <class 'builtin_function_or_method'>\n"
     ]
    },
    {
     "name": "stderr",
     "output_type": "stream",
     "text": [
      "127.0.0.1 - - [26/Jan/2022 05:53:33] \"\u001b[35m\u001b[1mGET /scrape HTTP/1.1\u001b[0m\" 500 -\n"
     ]
    }
   ],
   "source": [
    "if __name__ == \"__main__\":\n",
    "    app.run()"
   ]
  }
 ],
 "metadata": {
  "kernelspec": {
   "display_name": "PythonData",
   "language": "python",
   "name": "pythondata"
  },
  "language_info": {
   "codemirror_mode": {
    "name": "ipython",
    "version": 3
   },
   "file_extension": ".py",
   "mimetype": "text/x-python",
   "name": "python",
   "nbconvert_exporter": "python",
   "pygments_lexer": "ipython3",
   "version": "3.6.10"
  }
 },
 "nbformat": 4,
 "nbformat_minor": 5
}
